{"trial_id": "00", "hyperparameters": {"space": [{"class_name": "Int", "config": {"name": "conv_1", "default": null, "conditions": [], "min_value": 32, "max_value": 96, "step": 32, "sampling": "linear"}}, {"class_name": "Int", "config": {"name": "Bi_LSTM_1", "default": null, "conditions": [], "min_value": 64, "max_value": 256, "step": 32, "sampling": "linear"}}, {"class_name": "Int", "config": {"name": "Bi_LSTM_2", "default": null, "conditions": [], "min_value": 64, "max_value": 256, "step": 32, "sampling": "linear"}}, {"class_name": "Int", "config": {"name": "Dense_1", "default": null, "conditions": [], "min_value": 16, "max_value": 64, "step": 16, "sampling": "linear"}}, {"class_name": "Int", "config": {"name": "Dense_2", "default": null, "conditions": [], "min_value": 8, "max_value": 32, "step": 8, "sampling": "linear"}}, {"class_name": "Choice", "config": {"name": "learning_rate", "default": 0.01, "conditions": [], "values": [0.01, 0.05, 0.001, 0.005, 0.0001, 0.0005, 1e-05], "ordered": true}}, {"class_name": "Choice", "config": {"name": "loss", "default": "mse", "conditions": [], "values": ["mse", "mae"], "ordered": false}}], "values": {"conv_1": 64, "Bi_LSTM_1": 64, "Bi_LSTM_2": 128, "Dense_1": 32, "Dense_2": 32, "learning_rate": 0.001, "loss": "mae"}}, "metrics": {"metrics": {}}, "score": null, "best_step": 0, "status": "FAILED", "message": "Traceback (most recent call last):\n  File \"/usr/local/bin/anaconda3/envs/tf_federated/lib/python3.9/site-packages/keras_tuner/engine/base_tuner.py\", line 270, in _try_run_and_update_trial\n    self._run_and_update_trial(trial, *fit_args, **fit_kwargs)\n  File \"/usr/local/bin/anaconda3/envs/tf_federated/lib/python3.9/site-packages/keras_tuner/engine/base_tuner.py\", line 235, in _run_and_update_trial\n    results = self.run_trial(trial, *fit_args, **fit_kwargs)\n  File \"/usr/local/bin/anaconda3/envs/tf_federated/lib/python3.9/site-packages/keras_tuner/engine/tuner.py\", line 287, in run_trial\n    obj_value = self._build_and_fit_model(trial, *args, **copied_kwargs)\n  File \"/usr/local/bin/anaconda3/envs/tf_federated/lib/python3.9/site-packages/keras_tuner/engine/tuner.py\", line 214, in _build_and_fit_model\n    results = self.hypermodel.fit(hp, model, *args, **kwargs)\n  File \"/usr/local/bin/anaconda3/envs/tf_federated/lib/python3.9/site-packages/keras_tuner/engine/hypermodel.py\", line 144, in fit\n    return model.fit(*args, **kwargs)\n  File \"/usr/local/bin/anaconda3/envs/tf_federated/lib/python3.9/site-packages/keras/utils/traceback_utils.py\", line 70, in error_handler\n    raise e.with_traceback(filtered_tb) from None\n  File \"/usr/local/bin/anaconda3/envs/tf_federated/lib/python3.9/site-packages/tensorflow/python/eager/execute.py\", line 52, in quick_execute\n    tensors = pywrap_tfe.TFE_Py_Execute(ctx._handle, device_name, op_name,\ntensorflow.python.framework.errors_impl.NotFoundError: Graph execution error:\n\nDetected at node 'sequential/conv1d/Conv1D' defined at (most recent call last):\n    File \"/var/share/rs1/projects/Fed_STLF/Bayesian_tuning.py\", line 145, in <module>\n      tuner.search(\n    File \"/usr/local/bin/anaconda3/envs/tf_federated/lib/python3.9/site-packages/keras_tuner/engine/base_tuner.py\", line 230, in search\n      self._try_run_and_update_trial(trial, *fit_args, **fit_kwargs)\n    File \"/usr/local/bin/anaconda3/envs/tf_federated/lib/python3.9/site-packages/keras_tuner/engine/base_tuner.py\", line 270, in _try_run_and_update_trial\n      self._run_and_update_trial(trial, *fit_args, **fit_kwargs)\n    File \"/usr/local/bin/anaconda3/envs/tf_federated/lib/python3.9/site-packages/keras_tuner/engine/base_tuner.py\", line 235, in _run_and_update_trial\n      results = self.run_trial(trial, *fit_args, **fit_kwargs)\n    File \"/usr/local/bin/anaconda3/envs/tf_federated/lib/python3.9/site-packages/keras_tuner/engine/tuner.py\", line 287, in run_trial\n      obj_value = self._build_and_fit_model(trial, *args, **copied_kwargs)\n    File \"/usr/local/bin/anaconda3/envs/tf_federated/lib/python3.9/site-packages/keras_tuner/engine/tuner.py\", line 214, in _build_and_fit_model\n      results = self.hypermodel.fit(hp, model, *args, **kwargs)\n    File \"/usr/local/bin/anaconda3/envs/tf_federated/lib/python3.9/site-packages/keras_tuner/engine/hypermodel.py\", line 144, in fit\n      return model.fit(*args, **kwargs)\n    File \"/usr/local/bin/anaconda3/envs/tf_federated/lib/python3.9/site-packages/keras/utils/traceback_utils.py\", line 65, in error_handler\n      return fn(*args, **kwargs)\n    File \"/usr/local/bin/anaconda3/envs/tf_federated/lib/python3.9/site-packages/keras/engine/training.py\", line 1685, in fit\n      tmp_logs = self.train_function(iterator)\n    File \"/usr/local/bin/anaconda3/envs/tf_federated/lib/python3.9/site-packages/keras/engine/training.py\", line 1284, in train_function\n      return step_function(self, iterator)\n    File \"/usr/local/bin/anaconda3/envs/tf_federated/lib/python3.9/site-packages/keras/engine/training.py\", line 1268, in step_function\n      outputs = model.distribute_strategy.run(run_step, args=(data,))\n    File \"/usr/local/bin/anaconda3/envs/tf_federated/lib/python3.9/site-packages/keras/engine/training.py\", line 1249, in run_step\n      outputs = model.train_step(data)\n    File \"/usr/local/bin/anaconda3/envs/tf_federated/lib/python3.9/site-packages/keras/engine/training.py\", line 1050, in train_step\n      y_pred = self(x, training=True)\n    File \"/usr/local/bin/anaconda3/envs/tf_federated/lib/python3.9/site-packages/keras/utils/traceback_utils.py\", line 65, in error_handler\n      return fn(*args, **kwargs)\n    File \"/usr/local/bin/anaconda3/envs/tf_federated/lib/python3.9/site-packages/keras/engine/training.py\", line 558, in __call__\n      return super().__call__(*args, **kwargs)\n    File \"/usr/local/bin/anaconda3/envs/tf_federated/lib/python3.9/site-packages/keras/utils/traceback_utils.py\", line 65, in error_handler\n      return fn(*args, **kwargs)\n    File \"/usr/local/bin/anaconda3/envs/tf_federated/lib/python3.9/site-packages/keras/engine/base_layer.py\", line 1145, in __call__\n      outputs = call_fn(inputs, *args, **kwargs)\n    File \"/usr/local/bin/anaconda3/envs/tf_federated/lib/python3.9/site-packages/keras/utils/traceback_utils.py\", line 96, in error_handler\n      return fn(*args, **kwargs)\n    File \"/usr/local/bin/anaconda3/envs/tf_federated/lib/python3.9/site-packages/keras/engine/sequential.py\", line 412, in call\n      return super().call(inputs, training=training, mask=mask)\n    File \"/usr/local/bin/anaconda3/envs/tf_federated/lib/python3.9/site-packages/keras/engine/functional.py\", line 512, in call\n      return self._run_internal_graph(inputs, training=training, mask=mask)\n    File \"/usr/local/bin/anaconda3/envs/tf_federated/lib/python3.9/site-packages/keras/engine/functional.py\", line 669, in _run_internal_graph\n      outputs = node.layer(*args, **kwargs)\n    File \"/usr/local/bin/anaconda3/envs/tf_federated/lib/python3.9/site-packages/keras/utils/traceback_utils.py\", line 65, in error_handler\n      return fn(*args, **kwargs)\n    File \"/usr/local/bin/anaconda3/envs/tf_federated/lib/python3.9/site-packages/keras/engine/base_layer.py\", line 1145, in __call__\n      outputs = call_fn(inputs, *args, **kwargs)\n    File \"/usr/local/bin/anaconda3/envs/tf_federated/lib/python3.9/site-packages/keras/utils/traceback_utils.py\", line 96, in error_handler\n      return fn(*args, **kwargs)\n    File \"/usr/local/bin/anaconda3/envs/tf_federated/lib/python3.9/site-packages/keras/layers/convolutional/base_conv.py\", line 290, in call\n      outputs = self.convolution_op(inputs, self.kernel)\n    File \"/usr/local/bin/anaconda3/envs/tf_federated/lib/python3.9/site-packages/keras/layers/convolutional/base_conv.py\", line 262, in convolution_op\n      return tf.nn.convolution(\nNode: 'sequential/conv1d/Conv1D'\nNo algorithm worked!  Error messages:\n  Profiling failure on CUDNN engine eng1{}: UNKNOWN: CUDNN_STATUS_ALLOC_FAILED\nin tensorflow/compiler/xla/stream_executor/cuda/cuda_dnn.cc(4639): 'status'\n  Profiling failure on CUDNN engine eng28{}: UNKNOWN: CUDNN_STATUS_ALLOC_FAILED\nin tensorflow/compiler/xla/stream_executor/cuda/cuda_dnn.cc(4639): 'status'\n  Profiling failure on CUDNN engine eng0{}: UNKNOWN: CUDNN_STATUS_ALLOC_FAILED\nin tensorflow/compiler/xla/stream_executor/cuda/cuda_dnn.cc(4639): 'status'\n  Profiling failure on CUDNN engine eng42{k2=2,k4=1,k5=0,k6=0,k7=0}: UNKNOWN: CUDNN_STATUS_EXECUTION_FAILED\nin tensorflow/compiler/xla/stream_executor/cuda/cuda_dnn.cc(4639): 'status'\n  Profiling failure on CUDNN engine eng42{k2=0,k4=1,k5=1,k6=0,k7=0}: UNKNOWN: CUDNN_STATUS_EXECUTION_FAILED\nin tensorflow/compiler/xla/stream_executor/cuda/cuda_dnn.cc(4639): 'status'\n  Profiling failure on CUDNN engine eng4{}: UNKNOWN: CUDNN_STATUS_INTERNAL_ERROR\nin tensorflow/compiler/xla/stream_executor/cuda/cuda_dnn.cc(4639): 'status'\n  Profiling failure on CUDNN engine eng3{k11=2}: UNKNOWN: CUDNN_STATUS_ALLOC_FAILED\nin tensorflow/compiler/xla/stream_executor/cuda/cuda_dnn.cc(4639): 'status'\n\t [[{{node sequential/conv1d/Conv1D}}]] [Op:__inference_train_function_13092]\n"}